#VRML_SIM R2025a utf8
# license: Apache License 2.0
# license url: http://www.apache.org/licenses/LICENSE-2.0
# This is a proto file for Webots for the LimoAckerman (x2 scale)
# Based on LimoAckerman.proto, all geometry scaled 2x

PROTO LimoAckerman_x2 [
  field  SFVec3f     translation     0 0 0
  field  SFRotation  rotation        0 0 1 0
  field  SFString    name            "LimoAckerman_x2"  # Is `Robot.name`.
  field  SFString    controller      "<extern>"          # Is `Robot.controller`.
  field  MFString    controllerArgs  []              # Is `Robot.controllerArgs`.
  field  SFString    customData      ""              # Is `Robot.customData`.
  field  SFBool      supervisor      FALSE           # Is `Robot.supervisor`.
  field  SFBool      synchronization TRUE            # Is `Robot.synchronization`.
  field  SFBool      selfCollision   FALSE           # Is `Robot.selfCollision`.
]
{
  Robot {
    translation IS translation
    rotation IS rotation
    controller IS controller
    controllerArgs IS controllerArgs
    customData IS customData
    supervisor IS supervisor
    synchronization IS synchronization
    selfCollision IS selfCollision
    children [
      # Base body visual mesh
      Pose {
        translation 0.000000 0.000000 -0.300000
        rotation 0.000000 0.000000 1.000000 1.570000
        children [
          DEF limo_base_visual CadShape {
            url "../resource/limo_description/meshes/limo_base_low_opt_x2.dae"
          }
        ]
      }
      # Lidar sensor
      Solid {
        translation 0.206000 0.000000 -0.068000
        children [
          Shape {
            appearance PBRAppearance {
              baseColor 0.500000 0.500000 0.500000
              roughness 1.000000
              metalness 0
            }
            geometry Cylinder {
              radius 0.04
              height 0.02
            }
          }
          Lidar {
            name "laser"
            fieldOfView 6.283180
            horizontalResolution 120
            numberOfLayers 1
            minRange 0.300000
            maxRange 15.000000
            noise 0.000667
            resolution 0.015000
          }
        ]
        name "laser_link"
        boundingObject Cylinder {
          radius 0.064
          height 0.032
        }
        physics Physics {
          density -1
          mass 0.100000
          centerOfMass [ 0.000000 0.000000 0.000000 ]
          inertiaMatrix [
            1.000000e-06 1.000000e-06 1.000000e-06
            0.000000e+00 0.000000e+00 0.000000e+00
          ]
        }
      }
      # Depth camera
      Solid {
        translation 0.168000 0.000000 0.060000
        children [
          Shape {
            appearance PBRAppearance {
              baseColor 0.500000 0.500000 0.500000
              roughness 1.000000
              metalness 0
            }
            geometry Box {
              size 0.040000 0.120000 0.030000
            }
          }
          Pose {
            translation 0 0 0
            rotation 0.577350 -0.577350 0.577350 2.094395
            children [
              RangeFinder {
                name "sensor_camera"
                fieldOfView 1.396263
                width 640
                height 480
                near 0.020000
                minRange 0.020000
              }
            ]
          }
        ]
        name "depth_camera_link"
        boundingObject Box {
          size 0.040000 0.120000 0.030000
        }
        physics Physics {
          density -1
          mass 0.100000
          centerOfMass [ 0.000000 0.000000 0.000000 ]
          inertiaMatrix [
            1.000000e-06 1.000000e-06 1.000000e-06
            0.000000e+00 0.000000e+00 0.000000e+00
          ]
        }
      }
      # IMU sensor
      Solid {
        translation 0.000000 0.000000 -0.200000
        children [
          Shape {
            appearance PBRAppearance {
              baseColor 0.500000 0.500000 0.500000
              roughness 1.000000
              metalness 0
            }
            geometry Box {
              size 0.002000 0.002000 0.002000
            }
          }
          InertialUnit {
            name "imu inertial"
          }
          Accelerometer {
            name "imu accelerometer"
          }
          Gyro {
            name "imu gyro"
          }
          Compass {
            name "imu compass"
          }
        ]
        name "imu_link"
        boundingObject Box {
          size 0.002000 0.002000 0.002000
        }
        physics Physics {
          density -1
          mass 0.010000
          centerOfMass [ 0.000000 0.000000 0.000000 ]
          inertiaMatrix [
            1.000000e-07 1.000000e-07 1.000000e-07
            0.000000e+00 0.000000e+00 0.000000e+00
          ]
        }
      }
      # ============================================
      # Front left: steering hinge + wheel
      # ============================================
      HingeJoint {
        jointParameters HingeJointParameters {
          axis 0.000000 0.000000 1.000000
          anchor 0.200000 0.140000 -0.201996
          dampingConstant 1.0
          staticFriction 2.0
        }
        device [
          RotationalMotor {
            name "left_steering_hinge_wheel"
            maxVelocity 0.5
            minPosition -0.523598767
            maxPosition 0.523598767
            maxTorque 5.0
          }
          PositionSensor {
            name "left_steering_hinge_wheel_sensor"
          }
        ]
        endPoint Solid {
          translation 0.200000 0.140000 -0.201996
          children [
            Shape {
              appearance PBRAppearance {
                baseColor 0.500000 0.500000 0.500000
                roughness 1.000000
                metalness 0
              }
              geometry Cylinder {
                radius 0.0002
                height 0.0002
              }
            }
            HingeJoint {
              jointParameters HingeJointParameters {
                axis 0.000000 1.000000 0.000000
              }
              device [
                PositionSensor {
                  name "front_left_wheel_sensor"
                }
              ]
              endPoint Solid {
                translation 0.000000 0.000000 0.000000
                children [
                  DEF limo_wheel_visual CadShape {
                    url "../resource/limo_description/meshes/limo_wheel_x2.dae"
                  }
                ]
                name "front_left_wheel_link"
                boundingObject Pose {
                  translation 0.000000 0.045000 0.000000
                  rotation 1.000000 0.000000 0.000000 1.570000
                  children [
                    Cylinder {
                      radius 0.090
                      height 0.090
                    }
                  ]
                }
                physics Physics {
                  density -1
                  mass 0.500000
                  centerOfMass [ 0.000000 0.000000 0.000000 ]
                  inertiaMatrix [
                    1.055000e-02 7.500000e-04 1.055000e-02
                    0.000000e+00 0.000000e+00 0.000000e+00
                  ]
                }
              }
            }
          ]
          name "left_steering_hinge"
          boundingObject Pose {
            translation 0.000000 0.045000 0.000000
            rotation 1.000000 0.000000 0.000000 1.570000
            children [
              Cylinder {
                radius 0.070
                height 0.090
              }
            ]
          }
          physics Physics {
            density -1
            mass 0.500000
            centerOfMass [ 0.000000 0.000000 0.000000 ]
            inertiaMatrix [
              1.055000e-02 7.500000e-04 1.055000e-02
              0.000000e+00 0.000000e+00 0.000000e+00
            ]
          }
        }
      }
      # ============================================
      # Front right: steering hinge + wheel
      # ============================================
      HingeJoint {
        jointParameters HingeJointParameters {
          axis 0.000000 0.000003 1.000000
          anchor 0.200000 -0.140000 -0.201996
          dampingConstant 1.0
          staticFriction 2.0
        }
        device [
          RotationalMotor {
            name "right_steering_hinge_wheel"
            maxVelocity 0.5
            minPosition -0.523598767
            maxPosition 0.523598767
            maxTorque 5.0
          }
          PositionSensor {
            name "right_steering_hinge_wheel_sensor"
          }
        ]
        endPoint Solid {
          translation 0.200000 -0.140000 -0.201996
          rotation 1.000000 0.000000 0.000000 3.141590
          children [
            Shape {
              appearance PBRAppearance {
                baseColor 0.500000 0.500000 0.500000
                roughness 1.000000
                metalness 0
              }
              geometry Cylinder {
                radius 0.0002
                height 0.0002
              }
            }
            HingeJoint {
              jointParameters HingeJointParameters {
                axis 0.000000 -1.000000 0.000000
              }
              device [
                PositionSensor {
                  name "front_right_wheel_sensor"
                }
              ]
              endPoint Solid {
                translation 0.000000 0.000000 0.000000
                children [
                  USE limo_wheel_visual
                ]
                name "front_right_wheel_link"
                boundingObject Pose {
                  translation 0.000000 0.045000 0.000000
                  rotation 1.000000 0.000000 0.000000 1.570000
                  children [
                    Cylinder {
                      radius 0.090
                      height 0.090
                    }
                  ]
                }
                physics Physics {
                  density -1
                  mass 0.500000
                  centerOfMass [ 0.000000 0.000000 0.000000 ]
                  inertiaMatrix [
                    1.055000e-02 7.500000e-04 1.055000e-02
                    0.000000e+00 0.000000e+00 0.000000e+00
                  ]
                }
              }
            }
          ]
          name "right_steering_hinge"
          boundingObject Pose {
            translation 0.000000 0.045000 0.000000
            rotation 1.000000 0.000000 0.000000 1.570000
            children [
              Cylinder {
                radius 0.070
                height 0.090
              }
            ]
          }
          physics Physics {
            density -1
            mass 0.500000
            centerOfMass [ 0.000000 0.000000 0.000000 ]
            inertiaMatrix [
              1.055000e-02 7.500000e-04 1.055000e-02
              0.000000e+00 0.000000e+00 0.000000e+00
            ]
          }
        }
      }
      # ============================================
      # Rear left wheel (drive only, no steering)
      # ============================================
      HingeJoint {
        jointParameters HingeJointParameters {
          axis 0.000000 1.000000 0.000000
          anchor -0.200000 0.140000 -0.201996
        }
        device [
          RotationalMotor {
            name "rear_left_wheel"
            maxTorque 10000
          }
          PositionSensor {
            name "rear_left_wheel_sensor"
          }
        ]
        endPoint Solid {
          translation -0.200000 0.140000 -0.201996
          children [
            USE limo_wheel_visual
          ]
          name "rear_left_wheel_link"
          boundingObject Pose {
            translation 0.000000 0.045000 0.000000
            rotation 1.000000 0.000000 0.000000 1.570000
            children [
              Cylinder {
                radius 0.090
                height 0.090
              }
            ]
          }
          physics Physics {
            density -1
            mass 0.500000
            centerOfMass [ 0.000000 0.000000 0.000000 ]
            inertiaMatrix [
              1.055000e-02 7.500000e-04 1.055000e-02
              0.000000e+00 0.000000e+00 0.000000e+00
            ]
          }
        }
      }
      # ============================================
      # Rear right wheel (drive only, no steering)
      # ============================================
      HingeJoint {
        jointParameters HingeJointParameters {
          axis 0.000000 1.000000 -0.000003
          anchor -0.200000 -0.140000 -0.201996
        }
        device [
          RotationalMotor {
            name "rear_right_wheel"
            maxTorque 10000
          }
          PositionSensor {
            name "rear_right_wheel_sensor"
          }
        ]
        endPoint Solid {
          translation -0.200000 -0.140000 -0.201996
          rotation 1.000000 0.000000 0.000000 3.141590
          children [
            USE limo_wheel_visual
          ]
          name "rear_right_wheel_link"
          boundingObject Pose {
            translation 0.000000 0.045000 0.000000
            rotation 1.000000 0.000000 0.000000 1.570000
            children [
              Cylinder {
                radius 0.090
                height 0.090
              }
            ]
          }
          physics Physics {
            density -1
            mass 0.500000
            centerOfMass [ 0.000000 0.000000 0.000000 ]
            inertiaMatrix [
              1.055000e-02 7.500000e-04 1.055000e-02
              0.000000e+00 0.000000e+00 0.000000e+00
            ]
          }
        }
      }
    ]
    name IS name
    boundingObject Box {
      size 0.520000 0.480000 0.400000
    }
    physics Physics {
      density -1
      mass 2.155700
      centerOfMass [ 0.000000 0.000000 0.000000 ]
      inertiaMatrix [
        9.600000e-01 3.840000e+00 3.840000e+00
        0.000000e+00 0.000000e+00 0.000000e+00
      ]
    }
  }
}
